Traceback (most recent call last):
  File "main_graph.py", line 215, in <module>
    f1 = main(cfg)
  File "main_graph.py", line 163, in main
    test_f1 = graph_classification_evaluation(model, cfg.eval_T, pooler, eval_loader,
  File "/ddm-nni/PROTEINS/evaluator.py", line 51, in graph_classification_evaluation
    out = model.embed(batch_g, feat, t)
  File "/ddm-nni/PROTEINS/models/DDM.py", line 120, in embed
    _, hidden = self.net(g, x_t=x_t, time_embed=time_embed)
  File "/root/miniconda3/envs/nni/lib/python3.8/site-packages/torch/nn/modules/module.py", line 1102, in _call_impl
    return forward_call(*input, **kwargs)
  File "/ddm-nni/PROTEINS/models/mlp_gat.py", line 65, in forward
    h_t = self.mlp_in_t(x_t)
  File "/root/miniconda3/envs/nni/lib/python3.8/site-packages/torch/nn/modules/module.py", line 1102, in _call_impl
    return forward_call(*input, **kwargs)
  File "/ddm-nni/PROTEINS/models/mlp_gat.py", line 116, in forward
    x = self.res_mlp(x)
  File "/root/miniconda3/envs/nni/lib/python3.8/site-packages/torch/nn/modules/module.py", line 1102, in _call_impl
    return forward_call(*input, **kwargs)
  File "/ddm-nni/PROTEINS/models/mlp_gat.py", line 100, in forward
    return self.fnc(x, *args, **kwargs) + x
  File "/root/miniconda3/envs/nni/lib/python3.8/site-packages/torch/nn/modules/module.py", line 1102, in _call_impl
    return forward_call(*input, **kwargs)
  File "/root/miniconda3/envs/nni/lib/python3.8/site-packages/torch/nn/modules/container.py", line 141, in forward
    input = module(input)
  File "/root/miniconda3/envs/nni/lib/python3.8/site-packages/torch/nn/modules/module.py", line 1102, in _call_impl
    return forward_call(*input, **kwargs)
  File "/root/miniconda3/envs/nni/lib/python3.8/site-packages/torch/nn/modules/batchnorm.py", line 168, in forward
    return F.batch_norm(
  File "/root/miniconda3/envs/nni/lib/python3.8/site-packages/torch/nn/functional.py", line 2282, in batch_norm
    return torch.batch_norm(
RuntimeError: CUDA error: device-side assert triggered
CUDA kernel errors might be asynchronously reported at some other API call,so the stacktrace below might be incorrect.
For debugging consider passing CUDA_LAUNCH_BLOCKING=1.
/pytorch/aten/src/ATen/native/cuda/ScatterGatherKernel.cu:111: operator(): block: [0,0,0], thread: [0,0,0] Assertion `idx_dim >= 0 && idx_dim < index_size && "index out of bounds"` failed.
/ddm-nni/PROTEINS/8uksh31v/trials/kUB8J/run.sh: line 10: 39277 Aborted                 (core dumped) python main_graph.py
