/pytorch/aten/src/ATen/native/cuda/ScatterGatherKernel.cu:111: operator(): block: [0,0,0], thread: [0,0,0] Assertion `idx_dim >= 0 && idx_dim < index_size && "index out of bounds"` failed.
Traceback (most recent call last):
  File "main_graph.py", line 214, in <module>
    f1 = main(cfg)
  File "main_graph.py", line 162, in main
    test_f1 = graph_classification_evaluation(model, cfg.eval_T, pooler, eval_loader,
  File "/ddm-nni/IMDB-B/evaluator.py", line 51, in graph_classification_evaluation
    out = model.embed(batch_g, feat, t)
  File "/ddm-nni/IMDB-B/models/DDM.py", line 120, in embed
    _, hidden = self.net(g, x_t=x_t, time_embed=time_embed)
  File "/root/miniconda3/envs/nni/lib/python3.8/site-packages/torch/nn/modules/module.py", line 1102, in _call_impl
    return forward_call(*input, **kwargs)
  File "/ddm-nni/IMDB-B/models/mlp_gat.py", line 72, in forward
    h_t = self.down_layers[l](g, h_t)
  File "/root/miniconda3/envs/nni/lib/python3.8/site-packages/torch/nn/modules/module.py", line 1102, in _call_impl
    return forward_call(*input, **kwargs)
  File "/root/miniconda3/envs/nni/lib/python3.8/site-packages/dgl/nn/pytorch/conv/gatconv.py", line 253, in forward
    if (graph.in_degrees() == 0).any():
  File "/root/miniconda3/envs/nni/lib/python3.8/site-packages/dgl/heterograph.py", line 3433, in in_degrees
    v = self.dstnodes(dsttype)
  File "/root/miniconda3/envs/nni/lib/python3.8/site-packages/dgl/view.py", line 49, in __call__
    ret = F.arange(
  File "/root/miniconda3/envs/nni/lib/python3.8/site-packages/dgl/backend/pytorch/tensor.py", line 402, in arange
    return th.arange(start, stop, dtype=dtype, device=ctx)
RuntimeError: CUDA error: device-side assert triggered
CUDA kernel errors might be asynchronously reported at some other API call,so the stacktrace below might be incorrect.
For debugging consider passing CUDA_LAUNCH_BLOCKING=1.
/ddm-nni/IMDB-B/lpvgaydw/trials/I8NNO/run.sh: line 10: 746576 Aborted                 (core dumped) python main_graph.py
