Traceback (most recent call last):
  File "main_node.py", line 183, in <module>
    f1 = main(cfg)
  File "main_node.py", line 129, in main
    acc = node_classification_evaluation(model, cfg.eval_T, graph, feat, num_classes,
  File "/ddm-nni/Cora/evaluator.py", line 24, in node_classification_evaluation
    repr = model.embed(graph, feat, t)
  File "/ddm-nni/Cora/models/DDM.py", line 132, in embed
    _, hidden = self.net(g, x_t=x_t, time_embed=time_embed)
  File "/root/miniconda3/envs/nni/lib/python3.8/site-packages/torch/nn/modules/module.py", line 1102, in _call_impl
    return forward_call(*input, **kwargs)
  File "/ddm-nni/Cora/models/mlp_gat.py", line 72, in forward
    h_t = self.down_layers[l](g, h_t)
  File "/root/miniconda3/envs/nni/lib/python3.8/site-packages/torch/nn/modules/module.py", line 1102, in _call_impl
    return forward_call(*input, **kwargs)
  File "/root/miniconda3/envs/nni/lib/python3.8/site-packages/dgl/nn/pytorch/conv/gatconv.py", line 253, in forward
    if (graph.in_degrees() == 0).any():
  File "/root/miniconda3/envs/nni/lib/python3.8/site-packages/dgl/heterograph.py", line 3433, in in_degrees
    v = self.dstnodes(dsttype)
  File "/root/miniconda3/envs/nni/lib/python3.8/site-packages/dgl/view.py", line 49, in __call__
    ret = F.arange(
  File "/root/miniconda3/envs/nni/lib/python3.8/site-packages/dgl/backend/pytorch/tensor.py", line 402, in arange
    return th.arange(start, stop, dtype=dtype, device=ctx)
RuntimeError: CUDA error: device-side assert triggered
CUDA kernel errors might be asynchronously reported at some other API call,so the stacktrace below might be incorrect.
For debugging consider passing CUDA_LAUNCH_BLOCKING=1.
/pytorch/aten/src/ATen/native/cuda/ScatterGatherKernel.cu:111: operator(): block: [0,0,0], thread: [0,0,0] Assertion `idx_dim >= 0 && idx_dim < index_size && "index out of bounds"` failed.
/ddm-nni/Cora/qxbzlrwf/trials/FH90w/run.sh: line 10: 34253 Aborted                 (core dumped) python main_node.py
